Workbook
Name FilterDateFrom: '01_Home'!$B$32
Name FilterDateTo: '01_Home'!$D$32
Name FilterCollection: '01_Home'!$F$32
Name FilterSKU: '01_Home'!$H$32
Name FilterSupplier: '01_Home'!$J$32
Name FilterLocation: '01_Home'!$L$32
Name FilterCampaign: '01_Home'!$N$32
Name OverallDataQualityPct: '14_Data_Quality'!$C$40
Name SetCompanyName: '15_Settings'!$C$13
Name SetBaseCurrency: '15_Settings'!$C$14
Name SetReportingCurrency: '15_Settings'!$C$15
Name SetFiscalYearStartMonth: '15_Settings'!$C$16
Name SetDefaultVATRate: '15_Settings'!$C$17
Name SetTargetGrossMargin: '15_Settings'!$C$18
Name SetShopifyStoreDomain: '15_Settings'!$C$23
Name SetShopifyAPIVersion: '15_Settings'!$C$24
Name SetLookbackDaysIncrementalRefresh: '15_Settings'!$C$25
Name SetHistoricalBackfillStartDate: '15_Settings'!$C$26
Name SetMaxPagesPerRefreshSafetyCap: '15_Settings'!$C$27
Name BusinessHealthScore: 'BI_HealthScore'!$C$26
Name BusinessHealthStatus: 'BI_HealthScore'!$C$27
Name LookupExpenseCategory: =tbl_LookupExpenseCategory[Expense Category]
Name LookupExpenseSubcategory: =tbl_LookupExpenseSubcategory[Expense Subcategory]
Name LookupCostCenter: =tbl_LookupCostCenter[Cost Center]
Name LookupPaymentMethod: =tbl_LookupPaymentMethod[Payment Method]
Name LookupCurrency: =tbl_LookupCurrency[Currency]
Name LookupSupplierType: =tbl_LookupSupplierType[Supplier Type]
Name LookupSupplierStatus: =tbl_LookupSupplierStatus[Supplier Status]
Name LookupCapitalTransactionType: =tbl_LookupCapitalTransactionType[Capital Transaction Type]
Name LookupPOStatus: =tbl_LookupPOStatus[PO Status]
Name LookupWarehouse: =tbl_LookupWarehouse[Warehouse]
Name LookupOwner: =tbl_LookupOwner[Owner]
Name LookupBudgetPeriod: =tbl_LookupBudgetPeriod[Budget Period]
Name LookupBudgetCategory: =tbl_LookupBudgetCategory[Budget Category]
Name LookupAlertSeverity: =tbl_LookupAlertSeverity[Alert Severity]
Name SupplierNameList: =tbl_SupplierMaster[Supplier Name]
Name POHeaderList: =tbl_POHeader[PO Number]
Name SKUList: =tbl_RAW_Variants[SKU]
Name CollectionTitleList: =tbl_RAW_Collections[Title]

Sheet 01_Home
A1: PASSRESS MIS — Home
A2: PASSRESS MIS | Home
A3: Sheet Documentation (use the + outline control at left to expand)
A4: Purpose | B4: Landing page and navigation hub for the entire workbook.
A5: Input tables | B5: None — display only.
A6: Output tables | B6: None.
A7: Relationships | B7: Links to all 14 other visible sheets. Reads workbook status from LOG_RefreshHistory and LOG_DataQuality.
A8: Future data source | B8: LOG_RefreshHistory (last refresh timestamp), LOG_DataQuality (overall status) — wired in Phase 2/4.
B11: LAST REFRESH | D11: DATA QUALITY | F11: WORKBOOK VERSION | H11: PHASE COMPLETED
B12: =IFERROR(TEXT(MAX(tbl_LOG_RefreshHistory[Timestamp]),"dd-mmm hh:mm"),"—") | D12: =IFERROR(TEXT(OverallDataQualityPct,"0.0%"),"—") | F12: =INDEX(tbl_VersionLog[Version],COUNTA(tbl_VersionLog[Version])) | H12: =INDEX(tbl_VersionLog[Phase],COUNTA(tbl_VersionLog[Phase]))
B15: NAVIGATION
B16: 02 Partner Dashboard | D16: 03 CEO Dashboard | F16: 04 Sales | H16: 05 Products
B19: 06 Customers | D19: 07 Inventory | F19: 08 Finance | H19: 09 Profitability
B22: 10 Expenses | D22: 11 Capital | F22: 12 Suppliers | H22: 13 Marketing
B25: 14 Data Quality | D25: 15 Settings
B30: GLOBAL FILTERS (orange cells = type or choose 'All')
B31: Date From | D31: Date To | F31: Collection | H31: SKU | J31: Supplier | L31: Location | N31: Campaign
B32: 2026-01-01 | D32: 2026-12-31 | F32: All | H32: All | J32: All | L32: All | N32: All (reserved — see Marketing-Ready Layer, not connected yet)
B34: REPORTS & TOOLS (hidden sheets — click to open, or right-click any tab → Unhide)
B35: → Daily Executive Brief
B36: → Workflow Dashboard
B38: Phase 6 build. See 15_Settings' Version Log for the full phase history and roadmap. Data shown on dashboards resolves once the Data Model is wired — see power-query/README.md and dax/README.md.

Sheet 02_Partner_Dashboard
A1: Partner Dashboard
A2: PASSRESS MIS | Home ▸ Partner Dashboard
A3: Sheet Documentation (use the + outline control at left to expand)
A4: Purpose | B4: Executive view for business partners — the headline numbers only, no operational drill-down. Simple, beautiful, minimal by design.
A5: Input tables | B5: The Data Model (dax/MEASURES.md, dax/PHASE5_MEASURES_ADDENDUM.md) via CUBEVALUE/CUBESET — no PivotTable required.
A6: Output tables | B6: 5 KPI cards, one 12-month trend chart, a live Top 5 Products list, Key Insights (from BI_Insights).
A7: Relationships | B7: Reads the Data Model directly; BI_Insights supplies the insight text shown here.
A8: Future data source | B8: Already live: every number resolves once the Data Model + measures are wired — see power-query/README.md and dax/README.md. Until then, cards show 0 and the chart is flat — expected, not an error.
B11: REVENUE | D11: NET PROFIT | F11: MARGIN % | H11: CASH POSITION | J11: ORDERS
B12: =CUBEVALUE("ThisWorkbookDataModel","[Measures].[Net Sales]") | D12: =CUBEVALUE("ThisWorkbookDataModel","[Measures].[Net Profit]") | F12: =CUBEVALUE("ThisWorkbookDataModel","[Measures].[Gross Margin %]") | H12: =CUBEVALUE("ThisWorkbookDataModel","[Measures].[Cash Position (Direct, Cumulative)]") | J12: =CUBEVALUE("ThisWorkbookDataModel","[Measures].[Order Count]")
B15: ↓ Drill into Sales
B17: MONTHLY TREND — NET SALES
B18: Net Sales — trailing 12 months
C19: =TEXT(EDATE(TODAY(),-11),"mmm-yy") | D19: =TEXT(EDATE(TODAY(),-10),"mmm-yy") | E19: =TEXT(EDATE(TODAY(),-9),"mmm-yy") | F19: =TEXT(EDATE(TODAY(),-8),"mmm-yy") | G19: =TEXT(EDATE(TODAY(),-7),"mmm-yy") | H19: =TEXT(EDATE(TODAY(),-6),"mmm-yy") | I19: =TEXT(EDATE(TODAY(),-5),"mmm-yy") | J19: =TEXT(EDATE(TODAY(),-4),"mmm-yy") | K19: =TEXT(EDATE(TODAY(),-3),"mmm-yy") | L19: =TEXT(EDATE(TODAY(),-2),"mmm-yy") | M19: =TEXT(EDATE(TODAY(),-1),"mmm-yy") | N19: =TEXT(EDATE(TODAY(),0),"mmm-yy")
C20: =CUBEVALUE("ThisWorkbookDataModel","[Measures].[Net Sales]","[DIM_Date].[Year].&["&YEAR(EDATE(TODAY(),-11))&"]","[DIM_Date].[Month].&["&MONTH(EDATE(TODAY(),-11))&"]") | D20: =CUBEVALUE("ThisWorkbookDataModel","[Measures].[Net Sales]","[DIM_Date].[Year].&["&YEAR(EDATE(TODAY(),-10))&"]","[DIM_Date].[Month].&["&MONTH(EDATE(TODAY(),-10))&"]") | E20: =CUBEVALUE("ThisWorkbookDataModel","[Measures].[Net Sales]","[DIM_Date].[Year].&["&YEAR(EDATE(TODAY(),-9))&"]","[DIM_Date].[Month].&["&MONTH(EDATE(TODAY(),-9))&"]") | F20: =CUBEVALUE("ThisWorkbookDataModel","[Measures].[Net Sales]","[DIM_Date].[Year].&["&YEAR(EDATE(TODAY(),-8))&"]","[DIM_Date].[Month].&["&MONTH(EDATE(TODAY(),-8))&"]") | G20: =CUBEVALUE("ThisWorkbookDataModel","[Measures].[Net Sales]","[DIM_Date].[Year].&["&YEAR(EDATE(TODAY(),-7))&"]","[DIM_Date].[Month].&["&MONTH(EDATE(TODAY(),-7))&"]") | H20: =CUBEVALUE("ThisWorkbookDataModel","[Measures].[Net Sales]","[DIM_Date].[Year].&["&YEAR(EDATE(TODAY(),-6))&"]","[DIM_Date].[Month].&["&MONTH(EDATE(TODAY(),-6))&"]") | I20: =CUBEVALUE("ThisWorkbookDataModel","[Measures].[Net Sales]","[DIM_Date].[Year].&["&YEAR(EDATE(TODAY(),-5))&"]","[DIM_Date].[Month].&["&MONTH(EDATE(TODAY(),-5))&"]") | J20: =CUBEVALUE("ThisWorkbookDataModel","[Measures].[Net Sales]","[DIM_Date].[Year].&["&YEAR(EDATE(TODAY(),-4))&"]","[DIM_Date].[Month].&["&MONTH(EDATE(TODAY(),-4))&"]") | K20: =CUBEVALUE("ThisWorkbookDataModel","[Measures].[Net Sales]","[DIM_Date].[Year].&["&YEAR(EDATE(TODAY(),-3))&"]","[DIM_Date].[Month].&["&MONTH(EDATE(TODAY(),-3))&"]") | L20: =CUBEVALUE("ThisWorkbookDataModel","[Measures].[Net Sales]","[DIM_Date].[Year].&["&YEAR(EDATE(TODAY(),-2))&"]","[DIM_Date].[Month].&["&MONTH(EDATE(TODAY(),-2))&"]") | M20: =CUBEVALUE("ThisWorkbookDataModel","[Measures].[Net Sales]","[DIM_Date].[Year].&["&YEAR(EDATE(TODAY(),-1))&"]","[DIM_Date].[Month].&["&MONTH(EDATE(TODAY(),-1))&"]") | N20: =CUBEVALUE("ThisWorkbookDataModel","[Measures].[Net Sales]","[DIM_Date].[Year].&["&YEAR(EDATE(TODAY(),0))&"]","[DIM_Date].[Month].&["&MONTH(EDATE(TODAY(),0))&"]")
B38: TOP 5 PRODUCTS (by Net Sales)
B39: Top 5 Products | F39: =CUBESET("ThisWorkbookDataModel","{[DIM_Product].[Title].Children}","Top 5 Products","BDESC","[Measures].[Net Sales]")
B40: =CUBERANKEDMEMBER("ThisWorkbookDataModel",$F$39,1) | D40: =CUBEVALUE("ThisWorkbookDataModel","[Measures].[Net Sales]",CUBERANKEDMEMBER("ThisWorkbookDataModel",$F$39,1))
B41: =CUBERANKEDMEMBER("ThisWorkbookDataModel",$F$39,2) | D41: =CUBEVALUE("ThisWorkbookDataModel","[Measures].[Net Sales]",CUBERANKEDMEMBER("ThisWorkbookDataModel",$F$39,2))
B42: =CUBERANKEDMEMBER("ThisWorkbookDataModel",$F$39,3) | D42: =CUBEVALUE("ThisWorkbookDataModel","[Measures].[Net Sales]",CUBERANKEDMEMBER("ThisWorkbookDataModel",$F$39,3))
B43: =CUBERANKEDMEMBER("ThisWorkbookDataModel",$F$39,4) | D43: =CUBEVALUE("ThisWorkbookDataModel","[Measures].[Net Sales]",CUBERANKEDMEMBER("ThisWorkbookDataModel",$F$39,4))
B44: =CUBERANKEDMEMBER("ThisWorkbookDataModel",$F$39,5) | D44: =CUBEVALUE("ThisWorkbookDataModel","[Measures].[Net Sales]",CUBERANKEDMEMBER("ThisWorkbookDataModel",$F$39,5))
B46: KEY INSIGHTS
B47: ="• "&IFERROR('BI_Insights'!D15,"(resolves once Data Model is wired)")
B48: ="• "&IFERROR('BI_Insights'!D16,"(resolves once Data Model is wired)")
B49: ="• "&IFERROR('BI_Insights'!D19,"(resolves once Data Model is wired)")
B50: ="• "&IFERROR('BI_Insights'!D20,"(resolves once Data Model is wired)")

Sheet 03_CEO_Dashboard
A1: CEO Dashboard
A2: PASSRESS MIS | Home ▸ CEO Dashboard
A3: Sheet Documentation (use the + outline control at left to expand)
A4: Purpose | B4: Management view: every KPI category, Budget/Forecast/Alerts summaries, and Business Insights — the full operational picture, unlike Partner Dashboard's deliberately minimal set.
A5: Input tables | B5: The Data Model (dax/MEASURES.md, dax/PHASE5_MEASURES_ADDENDUM.md) via CUBEVALUE; BI_Alerts, BI_Forecast, BI_Insights for their respective sections.
A6: Output tables | B6: 9 KPI-card sections + Budget/Forecast/Alerts/Insights reference tables.
A7: Relationships | B7: Reads the Data Model directly for KPI cards; reads BI_Alerts/BI_Forecast/BI_Insights directly (simple cell references, not re-derived CUBE formulas) for those three sections.
A8: Future data source | B8: Already live: every number resolves once the Data Model + measures are wired — see power-query/README.md and dax/README.md.
B11: FINANCIAL KPIs
B12: NET SALES | D12: GROSS PROFIT | F12: NET PROFIT | H12: CASH POSITION
B13: =CUBEVALUE("ThisWorkbookDataModel","[Measures].[Net Sales]") | D13: =CUBEVALUE("ThisWorkbookDataModel","[Measures].[Gross Profit]") | F13: =CUBEVALUE("ThisWorkbookDataModel","[Measures].[Net Profit]") | H13: =CUBEVALUE("ThisWorkbookDataModel","[Measures].[Cash Position (Direct, Cumulative)]")
B17: SALES KPIs
B18: ORDER COUNT | D18: AVERAGE ORDER VALUE | F18: UNITS SOLD | H18: REVENUE GROWTH % YOY
B19: =CUBEVALUE("ThisWorkbookDataModel","[Measures].[Order Count]") | D19: =CUBEVALUE("ThisWorkbookDataModel","[Measures].[Average Order Value]") | F19: =CUBEVALUE("ThisWorkbookDataModel","[Measures].[Units Sold]") | H19: =CUBEVALUE("ThisWorkbookDataModel","[Measures].[Revenue Growth % (YoY)]")
B22: ↓ Drill into Sales
B24: CUSTOMER KPIs
B25: NEW CUSTOMERS | D25: RETURNING CUSTOMERS | F25: CLV (HISTORICAL) | H25: RETENTION RATE (MOM)
B26: =CUBEVALUE("ThisWorkbookDataModel","[Measures].[New Customers]") | D26: =CUBEVALUE("ThisWorkbookDataModel","[Measures].[Returning Customers]") | F26: =CUBEVALUE("ThisWorkbookDataModel","[Measures].[Customer Lifetime Value (Historical)]") | H26: =CUBEVALUE("ThisWorkbookDataModel","[Measures].[Customer Retention Rate (MoM)]")
B29: ↓ Drill into Customers
B31: INVENTORY KPIs
B32: INVENTORY VALUE | D32: INVENTORY TURNOVER | F32: DAYS OF INVENTORY | H32: SLOW MOVING SKUS
B33: =CUBEVALUE("ThisWorkbookDataModel","[Measures].[Inventory Value]") | D33: =CUBEVALUE("ThisWorkbookDataModel","[Measures].[Inventory Turnover]") | F33: =CUBEVALUE("ThisWorkbookDataModel","[Measures].[Days of Inventory]") | H33: =CUBEVALUE("ThisWorkbookDataModel","[Measures].[Slow Moving SKU Count]")
B36: ↓ Drill into Inventory
B38: PROFITABILITY
B39: GROSS MARGIN % | D39: NET PROFIT MARGIN % | F39: BREAK-EVEN NET SALES
B40: =CUBEVALUE("ThisWorkbookDataModel","[Measures].[Gross Margin %]") | D40: =CUBEVALUE("ThisWorkbookDataModel","[Measures].[Net Profit Margin %]") | F40: =CUBEVALUE("ThisWorkbookDataModel","[Measures].[Break-Even Net Sales]")
B43: ↓ Drill into Profitability
B45: EXPENSE ANALYSIS
B46: OPERATING EXPENSES | D46: EXPENSE RATIO % | F46: EXPENSE ACTUAL VS BUDGET
B47: =CUBEVALUE("ThisWorkbookDataModel","[Measures].[Operating Expenses]") | D47: =CUBEVALUE("ThisWorkbookDataModel","[Measures].[Operating Expense Ratio %]") | F47: =CUBEVALUE("ThisWorkbookDataModel","[Measures].[Expense Actual vs Budget]")
B50: ↓ Drill into Expenses
B52: BUDGET (Actual vs Budget, current period)
B53: Category | C53: Actual | D53: Budget | E53: Variance
B54: Revenue | C54: =CUBEVALUE("ThisWorkbookDataModel","[Measures].[Net Sales]") | D54: =CUBEVALUE("ThisWorkbookDataModel","[Measures].[Revenue Budget (Period)]") | E54: =CUBEVALUE("ThisWorkbookDataModel","[Measures].[Revenue Actual vs Budget]")
B55: Expense | C55: =CUBEVALUE("ThisWorkbookDataModel","[Measures].[Operating Expenses]") | D55: =CUBEVALUE("ThisWorkbookDataModel","[Measures].[Expense Budget (Period)]") | E55: =CUBEVALUE("ThisWorkbookDataModel","[Measures].[Expense Actual vs Budget]")
B56: Purchasing | C56: =CUBEVALUE("ThisWorkbookDataModel","[Measures].[Cash Paid for Purchases]") | D56: =CUBEVALUE("ThisWorkbookDataModel","[Measures].[Purchasing Budget (Period)]") | E56: =CUBEVALUE("ThisWorkbookDataModel","[Measures].[Purchasing Actual vs Budget]")
B57: Profit | C57: =CUBEVALUE("ThisWorkbookDataModel","[Measures].[Net Profit]") | D57: =CUBEVALUE("ThisWorkbookDataModel","[Measures].[Profit Budget (Period)]") | E57: =CUBEVALUE("ThisWorkbookDataModel","[Measures].[Profit Actual vs Budget]")
B59: FORECAST (next period, rolling linear trend — see BI_Forecast)
B60: Metric | C60: Forecast (Next Month)
B61: Sales | C61: ='BI_Forecast'!E37
...

Sheet 04_Sales
A1: Sales
A2: PASSRESS MIS | Home ▸ Sales
A3: Sheet Documentation (use the + outline control at left to expand)
A4: Purpose | B4: Sales performance detail — orders, revenue, discounts, and returns by period, product, and channel.
A5: Input tables | B5: FACT_OrderLines, FACT_Refunds, DIM_Date, DIM_Product, DIM_Collection.
A6: Output tables | B6: Sales KPI row, Sales Trend chart (doubles as Sales by Date), Sales by Product / Sales by Collection breakdown tables (CUBE-function substitutes for a PivotTable — see dax/README.md), a link to the full Order List.
A7: Relationships | B7: FACT_OrderLines links to DIM_Date/DIM_Product/DIM_Collection; FACT_Refunds links to FACT_OrderLines.
A8: Future data source | B8: Live now: every card/table below reads dax/MEASURES.md's Gross Sales/Discounts/Returns/Net Sales measures (§0/§1) directly.
B11: GROSS SALES | D11: DISCOUNTS | F11: RETURNS | H11: NET SALES
B12: =CUBEVALUE("ThisWorkbookDataModel","[Measures].[Gross Sales]") | D12: =CUBEVALUE("ThisWorkbookDataModel","[Measures].[Discounts]") | F12: =CUBEVALUE("ThisWorkbookDataModel","[Measures].[Returns]") | H12: =CUBEVALUE("ThisWorkbookDataModel","[Measures].[Net Sales]")
B16: SALES TREND / SALES BY DATE (same Net Sales-by-month data — chart and table, not recomputed twice)
B17: Net Sales — trailing 12 months
C18: =TEXT(EDATE(TODAY(),-11),"mmm-yy") | D18: =TEXT(EDATE(TODAY(),-10),"mmm-yy") | E18: =TEXT(EDATE(TODAY(),-9),"mmm-yy") | F18: =TEXT(EDATE(TODAY(),-8),"mmm-yy") | G18: =TEXT(EDATE(TODAY(),-7),"mmm-yy") | H18: =TEXT(EDATE(TODAY(),-6),"mmm-yy") | I18: =TEXT(EDATE(TODAY(),-5),"mmm-yy") | J18: =TEXT(EDATE(TODAY(),-4),"mmm-yy") | K18: =TEXT(EDATE(TODAY(),-3),"mmm-yy") | L18: =TEXT(EDATE(TODAY(),-2),"mmm-yy") | M18: =TEXT(EDATE(TODAY(),-1),"mmm-yy") | N18: =TEXT(EDATE(TODAY(),0),"mmm-yy")
C19: =CUBEVALUE("ThisWorkbookDataModel","[Measures].[Net Sales]","[DIM_Date].[Year].&["&YEAR(EDATE(TODAY(),-11))&"]","[DIM_Date].[Month].&["&MONTH(EDATE(TODAY(),-11))&"]") | D19: =CUBEVALUE("ThisWorkbookDataModel","[Measures].[Net Sales]","[DIM_Date].[Year].&["&YEAR(EDATE(TODAY(),-10))&"]","[DIM_Date].[Month].&["&MONTH(EDATE(TODAY(),-10))&"]") | E19: =CUBEVALUE("ThisWorkbookDataModel","[Measures].[Net Sales]","[DIM_Date].[Year].&["&YEAR(EDATE(TODAY(),-9))&"]","[DIM_Date].[Month].&["&MONTH(EDATE(TODAY(),-9))&"]") | F19: =CUBEVALUE("ThisWorkbookDataModel","[Measures].[Net Sales]","[DIM_Date].[Year].&["&YEAR(EDATE(TODAY(),-8))&"]","[DIM_Date].[Month].&["&MONTH(EDATE(TODAY(),-8))&"]") | G19: =CUBEVALUE("ThisWorkbookDataModel","[Measures].[Net Sales]","[DIM_Date].[Year].&["&YEAR(EDATE(TODAY(),-7))&"]","[DIM_Date].[Month].&["&MONTH(EDATE(TODAY(),-7))&"]") | H19: =CUBEVALUE("ThisWorkbookDataModel","[Measures].[Net Sales]","[DIM_Date].[Year].&["&YEAR(EDATE(TODAY(),-6))&"]","[DIM_Date].[Month].&["&MONTH(EDATE(TODAY(),-6))&"]") | I19: =CUBEVALUE("ThisWorkbookDataModel","[Measures].[Net Sales]","[DIM_Date].[Year].&["&YEAR(EDATE(TODAY(),-5))&"]","[DIM_Date].[Month].&["&MONTH(EDATE(TODAY(),-5))&"]") | J19: =CUBEVALUE("ThisWorkbookDataModel","[Measures].[Net Sales]","[DIM_Date].[Year].&["&YEAR(EDATE(TODAY(),-4))&"]","[DIM_Date].[Month].&["&MONTH(EDATE(TODAY(),-4))&"]") | K19: =CUBEVALUE("ThisWorkbookDataModel","[Measures].[Net Sales]","[DIM_Date].[Year].&["&YEAR(EDATE(TODAY(),-3))&"]","[DIM_Date].[Month].&["&MONTH(EDATE(TODAY(),-3))&"]") | L19: =CUBEVALUE("ThisWorkbookDataModel","[Measures].[Net Sales]","[DIM_Date].[Year].&["&YEAR(EDATE(TODAY(),-2))&"]","[DIM_Date].[Month].&["&MONTH(EDATE(TODAY(),-2))&"]") | M19: =CUBEVALUE("ThisWorkbookDataModel","[Measures].[Net Sales]","[DIM_Date].[Year].&["&YEAR(EDATE(TODAY(),-1))&"]","[DIM_Date].[Month].&["&MONTH(EDATE(TODAY(),-1))&"]") | N19: =CUBEVALUE("ThisWorkbookDataModel","[Measures].[Net Sales]","[DIM_Date].[Year].&["&YEAR(EDATE(TODAY(),0))&"]","[DIM_Date].[Month].&["&MONTH(EDATE(TODAY(),0))&"]")
B37: SALES BY PRODUCT
B38: Sales by Product (Top 8 by Net Sales) | F38: =CUBESET("ThisWorkbookDataModel","{[DIM_Product].[Title].Children}","Sales by Product (Top 8 by Net Sales)","BDESC","[Measures].[Net Sales]")
B39: Title | C39: Net Sales
B40: =CUBERANKEDMEMBER("ThisWorkbookDataModel",$F$38,1) | C40: =CUBEVALUE("ThisWorkbookDataModel","[Measures].[Net Sales]",CUBERANKEDMEMBER("ThisWorkbookDataModel",$F$38,1))
B41: =CUBERANKEDMEMBER("ThisWorkbookDataModel",$F$38,2) | C41: =CUBEVALUE("ThisWorkbookDataModel","[Measures].[Net Sales]",CUBERANKEDMEMBER("ThisWorkbookDataModel",$F$38,2))
B42: =CUBERANKEDMEMBER("ThisWorkbookDataModel",$F$38,3) | C42: =CUBEVALUE("ThisWorkbookDataModel","[Measures].[Net Sales]",CUBERANKEDMEMBER("ThisWorkbookDataModel",$F$38,3))
B43: =CUBERANKEDMEMBER("ThisWorkbookDataModel",$F$38,4) | C43: =CUBEVALUE("ThisWorkbookDataModel","[Measures].[Net Sales]",CUBERANKEDMEMBER("ThisWorkbookDataModel",$F$38,4))
B44: =CUBERANKEDMEMBER("ThisWorkbookDataModel",$F$38,5) | C44: =CUBEVALUE("ThisWorkbookDataModel","[Measures].[Net Sales]",CUBERANKEDMEMBER("ThisWorkbookDataModel",$F$38,5))
B45: =CUBERANKEDMEMBER("ThisWorkbookDataModel",$F$38,6) | C45: =CUBEVALUE("ThisWorkbookDataModel","[Measures].[Net Sales]",CUBERANKEDMEMBER("ThisWorkbookDataModel",$F$38,6))
B46: =CUBERANKEDMEMBER("ThisWorkbookDataModel",$F$38,7) | C46: =CUBEVALUE("ThisWorkbookDataModel","[Measures].[Net Sales]",CUBERANKEDMEMBER("ThisWorkbookDataModel",$F$38,7))
B47: =CUBERANKEDMEMBER("ThisWorkbookDataModel",$F$38,8) | C47: =CUBEVALUE("ThisWorkbookDataModel","[Measures].[Net Sales]",CUBERANKEDMEMBER("ThisWorkbookDataModel",$F$38,8))
B50: SALES BY COLLECTION
B51: Sales by Collection (Top 8 by Net Sales) | F51: =CUBESET("ThisWorkbookDataModel","{[DIM_Collection].[Title].Children}","Sales by Collection (Top 8 by Net Sales)","BDESC","[Measures].[Net Sales]")
B52: Title | C52: Net Sales
B53: =CUBERANKEDMEMBER("ThisWorkbookDataModel",$F$51,1) | C53: =CUBEVALUE("ThisWorkbookDataModel","[Measures].[Net Sales]",CUBERANKEDMEMBER("ThisWorkbookDataModel",$F$51,1))
B54: =CUBERANKEDMEMBER("ThisWorkbookDataModel",$F$51,2) | C54: =CUBEVALUE("ThisWorkbookDataModel","[Measures].[Net Sales]",CUBERANKEDMEMBER("ThisWorkbookDataModel",$F$51,2))
B55: =CUBERANKEDMEMBER("ThisWorkbookDataModel",$F$51,3) | C55: =CUBEVALUE("ThisWorkbookDataModel","[Measures].[Net Sales]",CUBERANKEDMEMBER("ThisWorkbookDataModel",$F$51,3))
B56: =CUBERANKEDMEMBER("ThisWorkbookDataModel",$F$51,4) | C56: =CUBEVALUE("ThisWorkbookDataModel","[Measures].[Net Sales]",CUBERANKEDMEMBER("ThisWorkbookDataModel",$F$51,4))
B57: =CUBERANKEDMEMBER("ThisWorkbookDataModel",$F$51,5) | C57: =CUBEVALUE("ThisWorkbookDataModel","[Measures].[Net Sales]",CUBERANKEDMEMBER("ThisWorkbookDataModel",$F$51,5))
B58: =CUBERANKEDMEMBER("ThisWorkbookDataModel",$F$51,6) | C58: =CUBEVALUE("ThisWorkbookDataModel","[Measures].[Net Sales]",CUBERANKEDMEMBER("ThisWorkbookDataModel",$F$51,6))
B59: =CUBERANKEDMEMBER("ThisWorkbookDataModel",$F$51,7) | C59: =CUBEVALUE("ThisWorkbookDataModel","[Measures].[Net Sales]",CUBERANKEDMEMBER("ThisWorkbookDataModel",$F$51,7))
B60: =CUBERANKEDMEMBER("ThisWorkbookDataModel",$F$51,8) | C60: =CUBEVALUE("ThisWorkbookDataModel","[Measures].[Net Sales]",CUBERANKEDMEMBER("ThisWorkbookDataModel",$F$51,8))
B63: ORDER LIST
B64: [ Order List (Table) — Not implementable: No Order-level dimension exists in the Data Model — CUBE functions browse dimension members (Product/Collection/Customer/Location/Date), not individual fact rows, so a row-level order list can't be built this way without adding a new Data Model object, which is out of scope (architecture frozen). The full, live order list is RAW_Orders itself, already wired once Power Query is set up. ]
B68: ↓ Drill into Orders

Sheet 05_Products
A1: Products
A2: PASSRESS MIS | Home ▸ Products
A3: Sheet Documentation (use the + outline control at left to expand)
A4: Purpose | B4: Product-level performance dashboard PLUS, as of Phase 3, the Product Cost Master — the workbook's historical/versioned SKU costing table.
A5: Input tables | B5: DIM_Product, FACT_OrderLines (dashboard). RAW_Variants, RAW_Collections (Product Cost Master dropdowns).
A6: Output tables | B6: Product KPI row, Top 10 Products chart, Product Margin breakdown table (CUBE-function substitute for a PivotTable). tbl_ProductCostMaster feeding DIM_ProductCostHistory.
A7: Relationships | B7: DIM_Product links to FACT_OrderLines on ProductKey. tbl_ProductCostMaster[SKU] links to RAW_Variants[SKU]; COGS is matched via fn_GetEffectiveCost (SKU + order date against Effective From/To Date).
A8: Future data source | B8: Live now: dashboard reads dax/MEASURES.md measures directly. Product Cost Master is manual entry — see PHASE3_DOCUMENTATION.md §1.
B11: ACTIVE SKUS | D11: BEST SELLER | F11: AVG MARGIN % | H11: SLOW MOVERS | N11: =CUBESET("ThisWorkbookDataModel","{[DIM_Product].[Title].Children}","BestSellerProduct","BDESC","[Measures].[Net Sales]")
B12: N/A | D12: =CUBERANKEDMEMBER("ThisWorkbookDataModel",$N$11,1) | F12: =CUBEVALUE("ThisWorkbookDataModel","[Measures].[Gross Margin %]") | H12: =CUBEVALUE("ThisWorkbookDataModel","[Measures].[Slow Moving SKU Count]")
B16: TOP 10 PRODUCTS (by Net Sales)
N17: =CUBESET("ThisWorkbookDataModel","{[DIM_Product].[Title].Children}","Top10Products","BDESC","[Measures].[Net Sales]")
B18: =CUBERANKEDMEMBER("ThisWorkbookDataModel",$N$17,1) | D18: =CUBEVALUE("ThisWorkbookDataModel","[Measures].[Net Sales]",CUBERANKEDMEMBER("ThisWorkbookDataModel",$N$17,1))
B19: =CUBERANKEDMEMBER("ThisWorkbookDataModel",$N$17,2) | D19: =CUBEVALUE("ThisWorkbookDataModel","[Measures].[Net Sales]",CUBERANKEDMEMBER("ThisWorkbookDataModel",$N$17,2))
B20: =CUBERANKEDMEMBER("ThisWorkbookDataModel",$N$17,3) | D20: =CUBEVALUE("ThisWorkbookDataModel","[Measures].[Net Sales]",CUBERANKEDMEMBER("ThisWorkbookDataModel",$N$17,3))
B21: =CUBERANKEDMEMBER("ThisWorkbookDataModel",$N$17,4) | D21: =CUBEVALUE("ThisWorkbookDataModel","[Measures].[Net Sales]",CUBERANKEDMEMBER("ThisWorkbookDataModel",$N$17,4))
B22: =CUBERANKEDMEMBER("ThisWorkbookDataModel",$N$17,5) | D22: =CUBEVALUE("ThisWorkbookDataModel","[Measures].[Net Sales]",CUBERANKEDMEMBER("ThisWorkbookDataModel",$N$17,5))
B23: =CUBERANKEDMEMBER("ThisWorkbookDataModel",$N$17,6) | D23: =CUBEVALUE("ThisWorkbookDataModel","[Measures].[Net Sales]",CUBERANKEDMEMBER("ThisWorkbookDataModel",$N$17,6))
B24: =CUBERANKEDMEMBER("ThisWorkbookDataModel",$N$17,7) | D24: =CUBEVALUE("ThisWorkbookDataModel","[Measures].[Net Sales]",CUBERANKEDMEMBER("ThisWorkbookDataModel",$N$17,7))
B25: =CUBERANKEDMEMBER("ThisWorkbookDataModel",$N$17,8) | D25: =CUBEVALUE("ThisWorkbookDataModel","[Measures].[Net Sales]",CUBERANKEDMEMBER("ThisWorkbookDataModel",$N$17,8))
B26: =CUBERANKEDMEMBER("ThisWorkbookDataModel",$N$17,9) | D26: =CUBEVALUE("ThisWorkbookDataModel","[Measures].[Net Sales]",CUBERANKEDMEMBER("ThisWorkbookDataModel",$N$17,9))
B27: =CUBERANKEDMEMBER("ThisWorkbookDataModel",$N$17,10) | D27: =CUBEVALUE("ThisWorkbookDataModel","[Measures].[Net Sales]",CUBERANKEDMEMBER("ThisWorkbookDataModel",$N$17,10))
B29: PRODUCT MARGIN
B30: Product Margin (Top 8 by Gross Profit) | H30: =CUBESET("ThisWorkbookDataModel","{[DIM_Product].[Title].Children}","Product Margin (Top 8 by Gross Profit)","BDESC","[Measures].[Gross Profit]")
B31: Title | C31: Net Sales | D31: Gross Profit | E31: Gross Margin %
B32: =CUBERANKEDMEMBER("ThisWorkbookDataModel",$H$30,1) | C32: =CUBEVALUE("ThisWorkbookDataModel","[Measures].[Net Sales]",CUBERANKEDMEMBER("ThisWorkbookDataModel",$H$30,1)) | D32: =CUBEVALUE("ThisWorkbookDataModel","[Measures].[Gross Profit]",CUBERANKEDMEMBER("ThisWorkbookDataModel",$H$30,1)) | E32: =CUBEVALUE("ThisWorkbookDataModel","[Measures].[Gross Margin %]",CUBERANKEDMEMBER("ThisWorkbookDataModel",$H$30,1))
B33: =CUBERANKEDMEMBER("ThisWorkbookDataModel",$H$30,2) | C33: =CUBEVALUE("ThisWorkbookDataModel","[Measures].[Net Sales]",CUBERANKEDMEMBER("ThisWorkbookDataModel",$H$30,2)) | D33: =CUBEVALUE("ThisWorkbookDataModel","[Measures].[Gross Profit]",CUBERANKEDMEMBER("ThisWorkbookDataModel",$H$30,2)) | E33: =CUBEVALUE("ThisWorkbookDataModel","[Measures].[Gross Margin %]",CUBERANKEDMEMBER("ThisWorkbookDataModel",$H$30,2))
B34: =CUBERANKEDMEMBER("ThisWorkbookDataModel",$H$30,3) | C34: =CUBEVALUE("ThisWorkbookDataModel","[Measures].[Net Sales]",CUBERANKEDMEMBER("ThisWorkbookDataModel",$H$30,3)) | D34: =CUBEVALUE("ThisWorkbookDataModel","[Measures].[Gross Profit]",CUBERANKEDMEMBER("ThisWorkbookDataModel",$H$30,3)) | E34: =CUBEVALUE("ThisWorkbookDataModel","[Measures].[Gross Margin %]",CUBERANKEDMEMBER("ThisWorkbookDataModel",$H$30,3))
B35: =CUBERANKEDMEMBER("ThisWorkbookDataModel",$H$30,4) | C35: =CUBEVALUE("ThisWorkbookDataModel","[Measures].[Net Sales]",CUBERANKEDMEMBER("ThisWorkbookDataModel",$H$30,4)) | D35: =CUBEVALUE("ThisWorkbookDataModel","[Measures].[Gross Profit]",CUBERANKEDMEMBER("ThisWorkbookDataModel",$H$30,4)) | E35: =CUBEVALUE("ThisWorkbookDataModel","[Measures].[Gross Margin %]",CUBERANKEDMEMBER("ThisWorkbookDataModel",$H$30,4))
B36: =CUBERANKEDMEMBER("ThisWorkbookDataModel",$H$30,5) | C36: =CUBEVALUE("ThisWorkbookDataModel","[Measures].[Net Sales]",CUBERANKEDMEMBER("ThisWorkbookDataModel",$H$30,5)) | D36: =CUBEVALUE("ThisWorkbookDataModel","[Measures].[Gross Profit]",CUBERANKEDMEMBER("ThisWorkbookDataModel",$H$30,5)) | E36: =CUBEVALUE("ThisWorkbookDataModel","[Measures].[Gross Margin %]",CUBERANKEDMEMBER("ThisWorkbookDataModel",$H$30,5))
B37: =CUBERANKEDMEMBER("ThisWorkbookDataModel",$H$30,6) | C37: =CUBEVALUE("ThisWorkbookDataModel","[Measures].[Net Sales]",CUBERANKEDMEMBER("ThisWorkbookDataModel",$H$30,6)) | D37: =CUBEVALUE("ThisWorkbookDataModel","[Measures].[Gross Profit]",CUBERANKEDMEMBER("ThisWorkbookDataModel",$H$30,6)) | E37: =CUBEVALUE("ThisWorkbookDataModel","[Measures].[Gross Margin %]",CUBERANKEDMEMBER("ThisWorkbookDataModel",$H$30,6))
B38: =CUBERANKEDMEMBER("ThisWorkbookDataModel",$H$30,7) | C38: =CUBEVALUE("ThisWorkbookDataModel","[Measures].[Net Sales]",CUBERANKEDMEMBER("ThisWorkbookDataModel",$H$30,7)) | D38: =CUBEVALUE("ThisWorkbookDataModel","[Measures].[Gross Profit]",CUBERANKEDMEMBER("ThisWorkbookDataModel",$H$30,7)) | E38: =CUBEVALUE("ThisWorkbookDataModel","[Measures].[Gross Margin %]",CUBERANKEDMEMBER("ThisWorkbookDataModel",$H$30,7))
B39: =CUBERANKEDMEMBER("ThisWorkbookDataModel",$H$30,8) | C39: =CUBEVALUE("ThisWorkbookDataModel","[Measures].[Net Sales]",CUBERANKEDMEMBER("ThisWorkbookDataModel",$H$30,8)) | D39: =CUBEVALUE("ThisWorkbookDataModel","[Measures].[Gross Profit]",CUBERANKEDMEMBER("ThisWorkbookDataModel",$H$30,8)) | E39: =CUBEVALUE("ThisWorkbookDataModel","[Measures].[Gross Margin %]",CUBERANKEDMEMBER("ThisWorkbookDataModel",$H$30,8))
B42: VARIANT DETAIL
B43: [ Variant Detail (PivotTable) — Not implementable: SKU/variant attributes (Price, Compare-at Price, current Unit Cost, Status) are row-level dimension data, not aggregate measures — CUBE functions can rank/aggregate a dimension's members by a measure (used above), but can't display raw per-row attribute columns the way a real PivotTable's row area can. Full variant detail is on DIM_Product / RAW_Variants directly. ]
B47: ↓ Drill into Product
B49: KNOWN GAPS ON THIS SHEET (documented, not silently missing)
B50: Active SKUs: No DAX measure counts total/active SKUs — dax/MEASURES.md's Product Profitability section (§4) covers profit PER SKU via PivotTable row context, not a SKU-count aggregate. A DISTINCTCOUNT(DIM_Product[SKU]) measure doesn't exist in the library; adding one is out of this phase's reuse-only scope.
B53: PRODUCT COST MASTER (Phase 3 — green cells = type here; Cost ID, Total Landed Cost, Expected Gross Margin %, and the overlap warning are automatic)
B54: Historical costing: never edit or delete a past row when a cost changes — add a NEW row for the new cost with its own Effective From Date, and set the OLD row's Effective To Date to the day before and its Active Flag to Inactive. Phase 4's COGS calculation will match each order line to the cost row whose SKU matches and whose Effective From/To range contains the order's date — so past orders keep using the cost that was actually active when they happened, even after costs change.
...

Sheet 06_Customers
A1: Customers
A2: PASSRESS MIS | Home ▸ Customers
A3: Sheet Documentation (use the + outline control at left to expand)
A4: Purpose | B4: Customer analytics — lifetime value, repeat-purchase rate, and geography.
A5: Input tables | B5: DIM_Customer, FACT_OrderLines.
A6: Output tables | B6: Customer KPI row, Top Customers / Geography breakdown tables (CUBE-function substitutes for a PivotTable).
A7: Relationships | B7: DIM_Customer links to FACT_OrderLines on CustomerKey.
A8: Future data source | B8: Live now: reads dax/MEASURES.md's Customer Metrics measures (§5) directly.
B11: TOTAL CUSTOMERS | D11: NEW CUSTOMERS | F11: REPEAT RATE % | H11: AVG LTV
B12: N/A | D12: =CUBEVALUE("ThisWorkbookDataModel","[Measures].[New Customers]") | F12: =CUBEVALUE("ThisWorkbookDataModel","[Measures].[Repeat Customer % Actual]") | H12: =CUBEVALUE("ThisWorkbookDataModel","[Measures].[Customer Lifetime Value (Historical)]")
B16: COHORT TREND / COHORT TABLE
B17: [ Cohort Trend (Chart) / Cohort Table (PivotTable) — Not implementable: dax/MEASURES.md §5 documents Customer Cohorts as a PivotTable LAYOUT (DIM_Customer[CohortMonth] on rows, DIM_Date[MonthName]/[Year] on columns), not a single measure — it is inherently a 2-dimensional matrix. CUBE functions here rank a single dimension by a single measure (used everywhere else on this sheet); reproducing a true cohort matrix would need nested CUBESET/CUBEVALUE expressions per cohort-month x calendar-month intersection — the same class of advanced, execution-untestable MDX pattern already flagged as a confidence risk in dax/README.md and the Phase 5/6 documentation. Not attempted rather than shipped unverified. ]
B23: TOP CUSTOMERS
B24: Top Customers (Top 8 by Net Sales) | G24: =CUBESET("ThisWorkbookDataModel","{[DIM_Customer].[Name].Children}","Top Customers (Top 8 by Net Sales)","BDESC","[Measures].[Net Sales]")
B25: Name | C25: Net Sales | D25: CLV (Historical)
B26: =CUBERANKEDMEMBER("ThisWorkbookDataModel",$G$24,1) | C26: =CUBEVALUE("ThisWorkbookDataModel","[Measures].[Net Sales]",CUBERANKEDMEMBER("ThisWorkbookDataModel",$G$24,1)) | D26: =CUBEVALUE("ThisWorkbookDataModel","[Measures].[Customer Lifetime Value (Historical)]",CUBERANKEDMEMBER("ThisWorkbookDataModel",$G$24,1))
B27: =CUBERANKEDMEMBER("ThisWorkbookDataModel",$G$24,2) | C27: =CUBEVALUE("ThisWorkbookDataModel","[Measures].[Net Sales]",CUBERANKEDMEMBER("ThisWorkbookDataModel",$G$24,2)) | D27: =CUBEVALUE("ThisWorkbookDataModel","[Measures].[Customer Lifetime Value (Historical)]",CUBERANKEDMEMBER("ThisWorkbookDataModel",$G$24,2))
B28: =CUBERANKEDMEMBER("ThisWorkbookDataModel",$G$24,3) | C28: =CUBEVALUE("ThisWorkbookDataModel","[Measures].[Net Sales]",CUBERANKEDMEMBER("ThisWorkbookDataModel",$G$24,3)) | D28: =CUBEVALUE("ThisWorkbookDataModel","[Measures].[Customer Lifetime Value (Historical)]",CUBERANKEDMEMBER("ThisWorkbookDataModel",$G$24,3))
B29: =CUBERANKEDMEMBER("ThisWorkbookDataModel",$G$24,4) | C29: =CUBEVALUE("ThisWorkbookDataModel","[Measures].[Net Sales]",CUBERANKEDMEMBER("ThisWorkbookDataModel",$G$24,4)) | D29: =CUBEVALUE("ThisWorkbookDataModel","[Measures].[Customer Lifetime Value (Historical)]",CUBERANKEDMEMBER("ThisWorkbookDataModel",$G$24,4))
B30: =CUBERANKEDMEMBER("ThisWorkbookDataModel",$G$24,5) | C30: =CUBEVALUE("ThisWorkbookDataModel","[Measures].[Net Sales]",CUBERANKEDMEMBER("ThisWorkbookDataModel",$G$24,5)) | D30: =CUBEVALUE("ThisWorkbookDataModel","[Measures].[Customer Lifetime Value (Historical)]",CUBERANKEDMEMBER("ThisWorkbookDataModel",$G$24,5))
B31: =CUBERANKEDMEMBER("ThisWorkbookDataModel",$G$24,6) | C31: =CUBEVALUE("ThisWorkbookDataModel","[Measures].[Net Sales]",CUBERANKEDMEMBER("ThisWorkbookDataModel",$G$24,6)) | D31: =CUBEVALUE("ThisWorkbookDataModel","[Measures].[Customer Lifetime Value (Historical)]",CUBERANKEDMEMBER("ThisWorkbookDataModel",$G$24,6))
B32: =CUBERANKEDMEMBER("ThisWorkbookDataModel",$G$24,7) | C32: =CUBEVALUE("ThisWorkbookDataModel","[Measures].[Net Sales]",CUBERANKEDMEMBER("ThisWorkbookDataModel",$G$24,7)) | D32: =CUBEVALUE("ThisWorkbookDataModel","[Measures].[Customer Lifetime Value (Historical)]",CUBERANKEDMEMBER("ThisWorkbookDataModel",$G$24,7))
B33: =CUBERANKEDMEMBER("ThisWorkbookDataModel",$G$24,8) | C33: =CUBEVALUE("ThisWorkbookDataModel","[Measures].[Net Sales]",CUBERANKEDMEMBER("ThisWorkbookDataModel",$G$24,8)) | D33: =CUBEVALUE("ThisWorkbookDataModel","[Measures].[Customer Lifetime Value (Historical)]",CUBERANKEDMEMBER("ThisWorkbookDataModel",$G$24,8))
B36: GEOGRAPHY
B37: Geography (Net Sales by Country) | F37: =CUBESET("ThisWorkbookDataModel","{[DIM_Customer].[Country].Children}","Geography (Net Sales by Country)","BDESC","[Measures].[Net Sales]")
B38: Country | C38: Net Sales
B39: =CUBERANKEDMEMBER("ThisWorkbookDataModel",$F$37,1) | C39: =CUBEVALUE("ThisWorkbookDataModel","[Measures].[Net Sales]",CUBERANKEDMEMBER("ThisWorkbookDataModel",$F$37,1))
B40: =CUBERANKEDMEMBER("ThisWorkbookDataModel",$F$37,2) | C40: =CUBEVALUE("ThisWorkbookDataModel","[Measures].[Net Sales]",CUBERANKEDMEMBER("ThisWorkbookDataModel",$F$37,2))
B41: =CUBERANKEDMEMBER("ThisWorkbookDataModel",$F$37,3) | C41: =CUBEVALUE("ThisWorkbookDataModel","[Measures].[Net Sales]",CUBERANKEDMEMBER("ThisWorkbookDataModel",$F$37,3))
B42: =CUBERANKEDMEMBER("ThisWorkbookDataModel",$F$37,4) | C42: =CUBEVALUE("ThisWorkbookDataModel","[Measures].[Net Sales]",CUBERANKEDMEMBER("ThisWorkbookDataModel",$F$37,4))
B43: =CUBERANKEDMEMBER("ThisWorkbookDataModel",$F$37,5) | C43: =CUBEVALUE("ThisWorkbookDataModel","[Measures].[Net Sales]",CUBERANKEDMEMBER("ThisWorkbookDataModel",$F$37,5))
B44: =CUBERANKEDMEMBER("ThisWorkbookDataModel",$F$37,6) | C44: =CUBEVALUE("ThisWorkbookDataModel","[Measures].[Net Sales]",CUBERANKEDMEMBER("ThisWorkbookDataModel",$F$37,6))
B45: =CUBERANKEDMEMBER("ThisWorkbookDataModel",$F$37,7) | C45: =CUBEVALUE("ThisWorkbookDataModel","[Measures].[Net Sales]",CUBERANKEDMEMBER("ThisWorkbookDataModel",$F$37,7))
B46: =CUBERANKEDMEMBER("ThisWorkbookDataModel",$F$37,8) | C46: =CUBEVALUE("ThisWorkbookDataModel","[Measures].[Net Sales]",CUBERANKEDMEMBER("ThisWorkbookDataModel",$F$37,8))
B47: =CUBERANKEDMEMBER("ThisWorkbookDataModel",$F$37,9) | C47: =CUBEVALUE("ThisWorkbookDataModel","[Measures].[Net Sales]",CUBERANKEDMEMBER("ThisWorkbookDataModel",$F$37,9))
B48: =CUBERANKEDMEMBER("ThisWorkbookDataModel",$F$37,10) | C48: =CUBEVALUE("ThisWorkbookDataModel","[Measures].[Net Sales]",CUBERANKEDMEMBER("ThisWorkbookDataModel",$F$37,10))
B51: KNOWN GAPS ON THIS SHEET (documented, not silently missing)
B52: Total Customers: No DAX measure counts the full customer roster — dax/MEASURES.md defines [Customers Active (Current Period)] (period-filtered) and [New Customers] (first-order-in-period), but no all-time DISTINCTCOUNT(DIM_Customer[CustomerKey]) measure exists. Mapping this card to either existing measure would misrepresent what it actually counts, so it's left undocumented rather than mislabeled.

Sheet 07_Inventory
A1: Inventory
A2: PASSRESS MIS | Home ▸ Inventory
A3: Sheet Documentation (use the + outline control at left to expand)
A4: Purpose | B4: Stock levels, valuation, and turnover.
A5: Input tables | B5: FACT_InventoryMovements, DIM_Product, DIM_Location.
A6: Output tables | B6: Inventory KPI row, Stock Trend chart, Stock by Location / Low Stock / Inventory Valuation breakdown tables (CUBE-function substitutes for a PivotTable).
A7: Relationships | B7: FACT_InventoryMovements links to DIM_Product and DIM_Location.
A8: Future data source | B8: Live now: reads dax/MEASURES.md's Inventory Metrics measures (§6) directly.
B11: INVENTORY VALUE | D11: UNITS ON HAND | F11: INVENTORY TURNS | H11: STOCKOUT RISK
B12: =CUBEVALUE("ThisWorkbookDataModel","[Measures].[Inventory Value]") | D12: N/A | F12: =CUBEVALUE("ThisWorkbookDataModel","[Measures].[Inventory Turnover]") | H12: N/A
B16: STOCK TREND
B17: Uses [Average Inventory Value], not [Inventory Value]: dax/MEASURES.md §6 documents that [Inventory Value] always returns the MOST RECENT snapshot regardless of any date filter — charting it by month would repeat the same 'today' figure 12 times, not show a real trend. [Average Inventory Value] is the measure specifically documented as date-filter-aware, so it's the one that actually plots a trend.
B18: Average Inventory Value — trailing 12 months
C19: =TEXT(EDATE(TODAY(),-11),"mmm-yy") | D19: =TEXT(EDATE(TODAY(),-10),"mmm-yy") | E19: =TEXT(EDATE(TODAY(),-9),"mmm-yy") | F19: =TEXT(EDATE(TODAY(),-8),"mmm-yy") | G19: =TEXT(EDATE(TODAY(),-7),"mmm-yy") | H19: =TEXT(EDATE(TODAY(),-6),"mmm-yy") | I19: =TEXT(EDATE(TODAY(),-5),"mmm-yy") | J19: =TEXT(EDATE(TODAY(),-4),"mmm-yy") | K19: =TEXT(EDATE(TODAY(),-3),"mmm-yy") | L19: =TEXT(EDATE(TODAY(),-2),"mmm-yy") | M19: =TEXT(EDATE(TODAY(),-1),"mmm-yy") | N19: =TEXT(EDATE(TODAY(),0),"mmm-yy")
C20: =CUBEVALUE("ThisWorkbookDataModel","[Measures].[Average Inventory Value]","[DIM_Date].[Year].&["&YEAR(EDATE(TODAY(),-11))&"]","[DIM_Date].[Month].&["&MONTH(EDATE(TODAY(),-11))&"]") | D20: =CUBEVALUE("ThisWorkbookDataModel","[Measures].[Average Inventory Value]","[DIM_Date].[Year].&["&YEAR(EDATE(TODAY(),-10))&"]","[DIM_Date].[Month].&["&MONTH(EDATE(TODAY(),-10))&"]") | E20: =CUBEVALUE("ThisWorkbookDataModel","[Measures].[Average Inventory Value]","[DIM_Date].[Year].&["&YEAR(EDATE(TODAY(),-9))&"]","[DIM_Date].[Month].&["&MONTH(EDATE(TODAY(),-9))&"]") | F20: =CUBEVALUE("ThisWorkbookDataModel","[Measures].[Average Inventory Value]","[DIM_Date].[Year].&["&YEAR(EDATE(TODAY(),-8))&"]","[DIM_Date].[Month].&["&MONTH(EDATE(TODAY(),-8))&"]") | G20: =CUBEVALUE("ThisWorkbookDataModel","[Measures].[Average Inventory Value]","[DIM_Date].[Year].&["&YEAR(EDATE(TODAY(),-7))&"]","[DIM_Date].[Month].&["&MONTH(EDATE(TODAY(),-7))&"]") | H20: =CUBEVALUE("ThisWorkbookDataModel","[Measures].[Average Inventory Value]","[DIM_Date].[Year].&["&YEAR(EDATE(TODAY(),-6))&"]","[DIM_Date].[Month].&["&MONTH(EDATE(TODAY(),-6))&"]") | I20: =CUBEVALUE("ThisWorkbookDataModel","[Measures].[Average Inventory Value]","[DIM_Date].[Year].&["&YEAR(EDATE(TODAY(),-5))&"]","[DIM_Date].[Month].&["&MONTH(EDATE(TODAY(),-5))&"]") | J20: =CUBEVALUE("ThisWorkbookDataModel","[Measures].[Average Inventory Value]","[DIM_Date].[Year].&["&YEAR(EDATE(TODAY(),-4))&"]","[DIM_Date].[Month].&["&MONTH(EDATE(TODAY(),-4))&"]") | K20: =CUBEVALUE("ThisWorkbookDataModel","[Measures].[Average Inventory Value]","[DIM_Date].[Year].&["&YEAR(EDATE(TODAY(),-3))&"]","[DIM_Date].[Month].&["&MONTH(EDATE(TODAY(),-3))&"]") | L20: =CUBEVALUE("ThisWorkbookDataModel","[Measures].[Average Inventory Value]","[DIM_Date].[Year].&["&YEAR(EDATE(TODAY(),-2))&"]","[DIM_Date].[Month].&["&MONTH(EDATE(TODAY(),-2))&"]") | M20: =CUBEVALUE("ThisWorkbookDataModel","[Measures].[Average Inventory Value]","[DIM_Date].[Year].&["&YEAR(EDATE(TODAY(),-1))&"]","[DIM_Date].[Month].&["&MONTH(EDATE(TODAY(),-1))&"]") | N20: =CUBEVALUE("ThisWorkbookDataModel","[Measures].[Average Inventory Value]","[DIM_Date].[Year].&["&YEAR(EDATE(TODAY(),0))&"]","[DIM_Date].[Month].&["&MONTH(EDATE(TODAY(),0))&"]")
B38: STOCK BY LOCATION
B39: Stock by Location (Inventory Value) | F39: =CUBESET("ThisWorkbookDataModel","{[DIM_Location].[LocationName].Children}","Stock by Location (Inventory Value)","BDESC","[Measures].[Inventory Value]")
B40: LocationName | C40: Inventory Value
B41: =CUBERANKEDMEMBER("ThisWorkbookDataModel",$F$39,1) | C41: =CUBEVALUE("ThisWorkbookDataModel","[Measures].[Inventory Value]",CUBERANKEDMEMBER("ThisWorkbookDataModel",$F$39,1))
B42: =CUBERANKEDMEMBER("ThisWorkbookDataModel",$F$39,2) | C42: =CUBEVALUE("ThisWorkbookDataModel","[Measures].[Inventory Value]",CUBERANKEDMEMBER("ThisWorkbookDataModel",$F$39,2))
B43: =CUBERANKEDMEMBER("ThisWorkbookDataModel",$F$39,3) | C43: =CUBEVALUE("ThisWorkbookDataModel","[Measures].[Inventory Value]",CUBERANKEDMEMBER("ThisWorkbookDataModel",$F$39,3))
B44: =CUBERANKEDMEMBER("ThisWorkbookDataModel",$F$39,4) | C44: =CUBEVALUE("ThisWorkbookDataModel","[Measures].[Inventory Value]",CUBERANKEDMEMBER("ThisWorkbookDataModel",$F$39,4))
B45: =CUBERANKEDMEMBER("ThisWorkbookDataModel",$F$39,5) | C45: =CUBEVALUE("ThisWorkbookDataModel","[Measures].[Inventory Value]",CUBERANKEDMEMBER("ThisWorkbookDataModel",$F$39,5))
B46: =CUBERANKEDMEMBER("ThisWorkbookDataModel",$F$39,6) | C46: =CUBEVALUE("ThisWorkbookDataModel","[Measures].[Inventory Value]",CUBERANKEDMEMBER("ThisWorkbookDataModel",$F$39,6))
B47: =CUBERANKEDMEMBER("ThisWorkbookDataModel",$F$39,7) | C47: =CUBEVALUE("ThisWorkbookDataModel","[Measures].[Inventory Value]",CUBERANKEDMEMBER("ThisWorkbookDataModel",$F$39,7))
B48: =CUBERANKEDMEMBER("ThisWorkbookDataModel",$F$39,8) | C48: =CUBEVALUE("ThisWorkbookDataModel","[Measures].[Inventory Value]",CUBERANKEDMEMBER("ThisWorkbookDataModel",$F$39,8))
B49: =CUBERANKEDMEMBER("ThisWorkbookDataModel",$F$39,9) | C49: =CUBEVALUE("ThisWorkbookDataModel","[Measures].[Inventory Value]",CUBERANKEDMEMBER("ThisWorkbookDataModel",$F$39,9))
B50: =CUBERANKEDMEMBER("ThisWorkbookDataModel",$F$39,10) | C50: =CUBEVALUE("ThisWorkbookDataModel","[Measures].[Inventory Value]",CUBERANKEDMEMBER("ThisWorkbookDataModel",$F$39,10))
B53: LOW STOCK LIST
B54: Ranked by Inventory Value, ascending — a unit-count 'low stock' measure doesn't exist (see Units on Hand, above); Inventory Value ascending is the closest existing-measure proxy for 'what's running low.'
B55: Low Stock List (Bottom 8 by Inventory Value) | F55: =CUBESET("ThisWorkbookDataModel","{[DIM_Product].[Title].Children}","Low Stock List (Bottom 8 by Inventory Value)","BASC","[Measures].[Inventory Value]")
B56: Title | C56: Inventory Value
B57: =CUBERANKEDMEMBER("ThisWorkbookDataModel",$F$55,1) | C57: =CUBEVALUE("ThisWorkbookDataModel","[Measures].[Inventory Value]",CUBERANKEDMEMBER("ThisWorkbookDataModel",$F$55,1))
B58: =CUBERANKEDMEMBER("ThisWorkbookDataModel",$F$55,2) | C58: =CUBEVALUE("ThisWorkbookDataModel","[Measures].[Inventory Value]",CUBERANKEDMEMBER("ThisWorkbookDataModel",$F$55,2))
B59: =CUBERANKEDMEMBER("ThisWorkbookDataModel",$F$55,3) | C59: =CUBEVALUE("ThisWorkbookDataModel","[Measures].[Inventory Value]",CUBERANKEDMEMBER("ThisWorkbookDataModel",$F$55,3))
B60: =CUBERANKEDMEMBER("ThisWorkbookDataModel",$F$55,4) | C60: =CUBEVALUE("ThisWorkbookDataModel","[Measures].[Inventory Value]",CUBERANKEDMEMBER("ThisWorkbookDataModel",$F$55,4))
B61: =CUBERANKEDMEMBER("ThisWorkbookDataModel",$F$55,5) | C61: =CUBEVALUE("ThisWorkbookDataModel","[Measures].[Inventory Value]",CUBERANKEDMEMBER("ThisWorkbookDataModel",$F$55,5))
B62: =CUBERANKEDMEMBER("ThisWorkbookDataModel",$F$55,6) | C62: =CUBEVALUE("ThisWorkbookDataModel","[Measures].[Inventory Value]",CUBERANKEDMEMBER("ThisWorkbookDataModel",$F$55,6))
B63: =CUBERANKEDMEMBER("ThisWorkbookDataModel",$F$55,7) | C63: =CUBEVALUE("ThisWorkbookDataModel","[Measures].[Inventory Value]",CUBERANKEDMEMBER("ThisWorkbookDataModel",$F$55,7))
B64: =CUBERANKEDMEMBER("ThisWorkbookDataModel",$F$55,8) | C64: =CUBEVALUE("ThisWorkbookDataModel","[Measures].[Inventory Value]",CUBERANKEDMEMBER("ThisWorkbookDataModel",$F$55,8))
...

Sheet 08_Finance
A1: Finance
A2: PASSRESS MIS | Home ▸ Finance
A3: Sheet Documentation (use the + outline control at left to expand)
A4: Purpose | B4: Core management-basis financial statements — Profit & Loss and Cash Flow summary (not audited books).
A5: Input tables | B5: FACT_OrderLines, FACT_ManualExpenses, FACT_Payments, Chart of Accounts mapping (15_Settings).
A6: Output tables | B6: Finance KPI row, P&L Trend chart, P&L Statement and Cash Flow Statement (CUBE-function substitutes for a PivotTable, transcribing dax/MEASURES.md §1/§3's own documented measure maps into working formulas).
A7: Relationships | B7: Combines Shopify-sourced facts with manually entered FACT_ManualExpenses, categorized via the Chart of Accounts mapping table.
A8: Future data source | B8: Live now: every line reads an existing dax/MEASURES.md measure directly.
B11: NET SALES | D11: TOTAL EXPENSES | F11: NET PROFIT | H11: CASH BALANCE
B12: =CUBEVALUE("ThisWorkbookDataModel","[Measures].[Net Sales]") | D12: =CUBEVALUE("ThisWorkbookDataModel","[Measures].[Operating Expenses]") | F12: =CUBEVALUE("ThisWorkbookDataModel","[Measures].[Net Profit]") | H12: =CUBEVALUE("ThisWorkbookDataModel","[Measures].[Cash Position (Direct, Cumulative)]")
B16: P&L TREND (Net Sales / Operating Expenses / Net Profit)
C18: =TEXT(EDATE(TODAY(),-11),"mmm-yy") | D18: =TEXT(EDATE(TODAY(),-10),"mmm-yy") | E18: =TEXT(EDATE(TODAY(),-9),"mmm-yy") | F18: =TEXT(EDATE(TODAY(),-8),"mmm-yy") | G18: =TEXT(EDATE(TODAY(),-7),"mmm-yy") | H18: =TEXT(EDATE(TODAY(),-6),"mmm-yy") | I18: =TEXT(EDATE(TODAY(),-5),"mmm-yy") | J18: =TEXT(EDATE(TODAY(),-4),"mmm-yy") | K18: =TEXT(EDATE(TODAY(),-3),"mmm-yy") | L18: =TEXT(EDATE(TODAY(),-2),"mmm-yy") | M18: =TEXT(EDATE(TODAY(),-1),"mmm-yy") | N18: =TEXT(EDATE(TODAY(),0),"mmm-yy")
B19: Net Sales | C19: =CUBEVALUE("ThisWorkbookDataModel","[Measures].[Net Sales]","[DIM_Date].[Year].&["&YEAR(EDATE(TODAY(),-11))&"]","[DIM_Date].[Month].&["&MONTH(EDATE(TODAY(),-11))&"]") | D19: =CUBEVALUE("ThisWorkbookDataModel","[Measures].[Net Sales]","[DIM_Date].[Year].&["&YEAR(EDATE(TODAY(),-10))&"]","[DIM_Date].[Month].&["&MONTH(EDATE(TODAY(),-10))&"]") | E19: =CUBEVALUE("ThisWorkbookDataModel","[Measures].[Net Sales]","[DIM_Date].[Year].&["&YEAR(EDATE(TODAY(),-9))&"]","[DIM_Date].[Month].&["&MONTH(EDATE(TODAY(),-9))&"]") | F19: =CUBEVALUE("ThisWorkbookDataModel","[Measures].[Net Sales]","[DIM_Date].[Year].&["&YEAR(EDATE(TODAY(),-8))&"]","[DIM_Date].[Month].&["&MONTH(EDATE(TODAY(),-8))&"]") | G19: =CUBEVALUE("ThisWorkbookDataModel","[Measures].[Net Sales]","[DIM_Date].[Year].&["&YEAR(EDATE(TODAY(),-7))&"]","[DIM_Date].[Month].&["&MONTH(EDATE(TODAY(),-7))&"]") | H19: =CUBEVALUE("ThisWorkbookDataModel","[Measures].[Net Sales]","[DIM_Date].[Year].&["&YEAR(EDATE(TODAY(),-6))&"]","[DIM_Date].[Month].&["&MONTH(EDATE(TODAY(),-6))&"]") | I19: =CUBEVALUE("ThisWorkbookDataModel","[Measures].[Net Sales]","[DIM_Date].[Year].&["&YEAR(EDATE(TODAY(),-5))&"]","[DIM_Date].[Month].&["&MONTH(EDATE(TODAY(),-5))&"]") | J19: =CUBEVALUE("ThisWorkbookDataModel","[Measures].[Net Sales]","[DIM_Date].[Year].&["&YEAR(EDATE(TODAY(),-4))&"]","[DIM_Date].[Month].&["&MONTH(EDATE(TODAY(),-4))&"]") | K19: =CUBEVALUE("ThisWorkbookDataModel","[Measures].[Net Sales]","[DIM_Date].[Year].&["&YEAR(EDATE(TODAY(),-3))&"]","[DIM_Date].[Month].&["&MONTH(EDATE(TODAY(),-3))&"]") | L19: =CUBEVALUE("ThisWorkbookDataModel","[Measures].[Net Sales]","[DIM_Date].[Year].&["&YEAR(EDATE(TODAY(),-2))&"]","[DIM_Date].[Month].&["&MONTH(EDATE(TODAY(),-2))&"]") | M19: =CUBEVALUE("ThisWorkbookDataModel","[Measures].[Net Sales]","[DIM_Date].[Year].&["&YEAR(EDATE(TODAY(),-1))&"]","[DIM_Date].[Month].&["&MONTH(EDATE(TODAY(),-1))&"]") | N19: =CUBEVALUE("ThisWorkbookDataModel","[Measures].[Net Sales]","[DIM_Date].[Year].&["&YEAR(EDATE(TODAY(),0))&"]","[DIM_Date].[Month].&["&MONTH(EDATE(TODAY(),0))&"]")
B20: Operating Expenses | C20: =CUBEVALUE("ThisWorkbookDataModel","[Measures].[Operating Expenses]","[DIM_Date].[Year].&["&YEAR(EDATE(TODAY(),-11))&"]","[DIM_Date].[Month].&["&MONTH(EDATE(TODAY(),-11))&"]") | D20: =CUBEVALUE("ThisWorkbookDataModel","[Measures].[Operating Expenses]","[DIM_Date].[Year].&["&YEAR(EDATE(TODAY(),-10))&"]","[DIM_Date].[Month].&["&MONTH(EDATE(TODAY(),-10))&"]") | E20: =CUBEVALUE("ThisWorkbookDataModel","[Measures].[Operating Expenses]","[DIM_Date].[Year].&["&YEAR(EDATE(TODAY(),-9))&"]","[DIM_Date].[Month].&["&MONTH(EDATE(TODAY(),-9))&"]") | F20: =CUBEVALUE("ThisWorkbookDataModel","[Measures].[Operating Expenses]","[DIM_Date].[Year].&["&YEAR(EDATE(TODAY(),-8))&"]","[DIM_Date].[Month].&["&MONTH(EDATE(TODAY(),-8))&"]") | G20: =CUBEVALUE("ThisWorkbookDataModel","[Measures].[Operating Expenses]","[DIM_Date].[Year].&["&YEAR(EDATE(TODAY(),-7))&"]","[DIM_Date].[Month].&["&MONTH(EDATE(TODAY(),-7))&"]") | H20: =CUBEVALUE("ThisWorkbookDataModel","[Measures].[Operating Expenses]","[DIM_Date].[Year].&["&YEAR(EDATE(TODAY(),-6))&"]","[DIM_Date].[Month].&["&MONTH(EDATE(TODAY(),-6))&"]") | I20: =CUBEVALUE("ThisWorkbookDataModel","[Measures].[Operating Expenses]","[DIM_Date].[Year].&["&YEAR(EDATE(TODAY(),-5))&"]","[DIM_Date].[Month].&["&MONTH(EDATE(TODAY(),-5))&"]") | J20: =CUBEVALUE("ThisWorkbookDataModel","[Measures].[Operating Expenses]","[DIM_Date].[Year].&["&YEAR(EDATE(TODAY(),-4))&"]","[DIM_Date].[Month].&["&MONTH(EDATE(TODAY(),-4))&"]") | K20: =CUBEVALUE("ThisWorkbookDataModel","[Measures].[Operating Expenses]","[DIM_Date].[Year].&["&YEAR(EDATE(TODAY(),-3))&"]","[DIM_Date].[Month].&["&MONTH(EDATE(TODAY(),-3))&"]") | L20: =CUBEVALUE("ThisWorkbookDataModel","[Measures].[Operating Expenses]","[DIM_Date].[Year].&["&YEAR(EDATE(TODAY(),-2))&"]","[DIM_Date].[Month].&["&MONTH(EDATE(TODAY(),-2))&"]") | M20: =CUBEVALUE("ThisWorkbookDataModel","[Measures].[Operating Expenses]","[DIM_Date].[Year].&["&YEAR(EDATE(TODAY(),-1))&"]","[DIM_Date].[Month].&["&MONTH(EDATE(TODAY(),-1))&"]") | N20: =CUBEVALUE("ThisWorkbookDataModel","[Measures].[Operating Expenses]","[DIM_Date].[Year].&["&YEAR(EDATE(TODAY(),0))&"]","[DIM_Date].[Month].&["&MONTH(EDATE(TODAY(),0))&"]")
B21: Net Profit | C21: =CUBEVALUE("ThisWorkbookDataModel","[Measures].[Net Profit]","[DIM_Date].[Year].&["&YEAR(EDATE(TODAY(),-11))&"]","[DIM_Date].[Month].&["&MONTH(EDATE(TODAY(),-11))&"]") | D21: =CUBEVALUE("ThisWorkbookDataModel","[Measures].[Net Profit]","[DIM_Date].[Year].&["&YEAR(EDATE(TODAY(),-10))&"]","[DIM_Date].[Month].&["&MONTH(EDATE(TODAY(),-10))&"]") | E21: =CUBEVALUE("ThisWorkbookDataModel","[Measures].[Net Profit]","[DIM_Date].[Year].&["&YEAR(EDATE(TODAY(),-9))&"]","[DIM_Date].[Month].&["&MONTH(EDATE(TODAY(),-9))&"]") | F21: =CUBEVALUE("ThisWorkbookDataModel","[Measures].[Net Profit]","[DIM_Date].[Year].&["&YEAR(EDATE(TODAY(),-8))&"]","[DIM_Date].[Month].&["&MONTH(EDATE(TODAY(),-8))&"]") | G21: =CUBEVALUE("ThisWorkbookDataModel","[Measures].[Net Profit]","[DIM_Date].[Year].&["&YEAR(EDATE(TODAY(),-7))&"]","[DIM_Date].[Month].&["&MONTH(EDATE(TODAY(),-7))&"]") | H21: =CUBEVALUE("ThisWorkbookDataModel","[Measures].[Net Profit]","[DIM_Date].[Year].&["&YEAR(EDATE(TODAY(),-6))&"]","[DIM_Date].[Month].&["&MONTH(EDATE(TODAY(),-6))&"]") | I21: =CUBEVALUE("ThisWorkbookDataModel","[Measures].[Net Profit]","[DIM_Date].[Year].&["&YEAR(EDATE(TODAY(),-5))&"]","[DIM_Date].[Month].&["&MONTH(EDATE(TODAY(),-5))&"]") | J21: =CUBEVALUE("ThisWorkbookDataModel","[Measures].[Net Profit]","[DIM_Date].[Year].&["&YEAR(EDATE(TODAY(),-4))&"]","[DIM_Date].[Month].&["&MONTH(EDATE(TODAY(),-4))&"]") | K21: =CUBEVALUE("ThisWorkbookDataModel","[Measures].[Net Profit]","[DIM_Date].[Year].&["&YEAR(EDATE(TODAY(),-3))&"]","[DIM_Date].[Month].&["&MONTH(EDATE(TODAY(),-3))&"]") | L21: =CUBEVALUE("ThisWorkbookDataModel","[Measures].[Net Profit]","[DIM_Date].[Year].&["&YEAR(EDATE(TODAY(),-2))&"]","[DIM_Date].[Month].&["&MONTH(EDATE(TODAY(),-2))&"]") | M21: =CUBEVALUE("ThisWorkbookDataModel","[Measures].[Net Profit]","[DIM_Date].[Year].&["&YEAR(EDATE(TODAY(),-1))&"]","[DIM_Date].[Month].&["&MONTH(EDATE(TODAY(),-1))&"]") | N21: =CUBEVALUE("ThisWorkbookDataModel","[Measures].[Net Profit]","[DIM_Date].[Year].&["&YEAR(EDATE(TODAY(),0))&"]","[DIM_Date].[Month].&["&MONTH(EDATE(TODAY(),0))&"]")
B41: P&L STATEMENT
B42: P&L Statement (dax/MEASURES.md §1)
B43: Gross Sales | D43: =CUBEVALUE("ThisWorkbookDataModel","[Measures].[Gross Sales]")
B44: Discounts | D44: =CUBEVALUE("ThisWorkbookDataModel","[Measures].[Discounts]")
B45: Returns | D45: =CUBEVALUE("ThisWorkbookDataModel","[Measures].[Returns]")
B46: Net Sales | D46: =CUBEVALUE("ThisWorkbookDataModel","[Measures].[Net Sales]")
B47: COGS | D47: =CUBEVALUE("ThisWorkbookDataModel","[Measures].[COGS]")
B48: Gross Profit | D48: =CUBEVALUE("ThisWorkbookDataModel","[Measures].[Gross Profit]")
B49: Gross Margin % | D49: =CUBEVALUE("ThisWorkbookDataModel","[Measures].[Gross Margin %]")
B50: Operating Expenses | D50: =CUBEVALUE("ThisWorkbookDataModel","[Measures].[Operating Expenses]")
B51: EBITDA | D51: =CUBEVALUE("ThisWorkbookDataModel","[Measures].[EBITDA]")
B52: Net Profit | D52: =CUBEVALUE("ThisWorkbookDataModel","[Measures].[Net Profit]")
B55: CASH FLOW STATEMENT
B56: Cash Flow Statement (dax/MEASURES.md §3)
B57: Cash Flow from Operating Activities | D57: =CUBEVALUE("ThisWorkbookDataModel","[Measures].[Cash Flow from Operating Activities]")
B58: Cash Flow from Investing Activities | D58: =CUBEVALUE("ThisWorkbookDataModel","[Measures].[Cash Flow from Investing Activities]")
B59: Cash Flow from Financing Activities | D59: =CUBEVALUE("ThisWorkbookDataModel","[Measures].[Cash Flow from Financing Activities]")
B60: Net Cash Flow | D60: =CUBEVALUE("ThisWorkbookDataModel","[Measures].[Net Cash Flow]")
B61: Cash Position (Direct, Cumulative) | D61: =CUBEVALUE("ThisWorkbookDataModel","[Measures].[Cash Position (Direct, Cumulative)]")
B65: BUDGET (Phase 5 — green cells = type here; Budget ID is automatic)
B66: Leave Month blank for a YEARLY budget line (the whole year's target for that Year+Category); fill in Month for a MONTHLY line. dax/MEASURES_PHASE5.md's [Budget Variance] / [Forecast vs Budget] measures match Actuals to whichever grain a report is built at.
B68: Budget ID | C68: Year | D68: Month | E68: Category | F68: Budget Amount | G68: Notes
B69: ="BUD-"&TEXT(ROW()-68,"00000") | C69: 2026 | E69: Revenue | F69: 500000 | G69: EXAMPLE — 2026 annual revenue budget

Sheet 09_Profitability
A1: Profitability
A2: PASSRESS MIS | Home ▸ Profitability
A3: Sheet Documentation (use the + outline control at left to expand)
A4: Purpose | B4: Margin analysis — gross margin and profitability by product and collection.
A5: Input tables | B5: FACT_OrderLines, DIM_Product, DIM_Collection.
A6: Output tables | B6: Profitability KPI row, Margin Trend chart, Margin by Product / Margin by Collection breakdown tables (CUBE-function substitutes for a PivotTable).
A7: Relationships | B7: FACT_OrderLines carries both revenue and COGS at line grain, enabling margin by any dimension.
A8: Future data source | B8: Live now: reads dax/MEASURES.md's Gross Margin %/Gross Profit measures directly.
B11: GROSS MARGIN % | D11: CONTRIBUTION MARGIN % | F11: BEST MARGIN CATEGORY | H11: WORST MARGIN CATEGORY | N11: =CUBESET("ThisWorkbookDataModel","{[DIM_Product].[ProductType].Children}","BestMarginCategory","BDESC","[Measures].[Gross Margin %]")
B12: =CUBEVALUE("ThisWorkbookDataModel","[Measures].[Gross Margin %]") | D12: N/A | F12: =CUBERANKEDMEMBER("ThisWorkbookDataModel",$N$11,1) | H12: =CUBERANKEDMEMBER("ThisWorkbookDataModel",$N$12,1) | N12: =CUBESET("ThisWorkbookDataModel","{[DIM_Product].[ProductType].Children}","WorstMarginCategory","BASC","[Measures].[Gross Margin %]")
B16: "Category" = Shopify's ProductType field (DIM_Product[ProductType]) — the workbook has no separate Category dimension. Same ranking caveat as BI_Insights' Best/Weakest Seller: a low-volume ProductType can rank first/last on a thin sample.
B17: MARGIN TREND
B18: Gross Margin % — trailing 12 months
C19: =TEXT(EDATE(TODAY(),-11),"mmm-yy") | D19: =TEXT(EDATE(TODAY(),-10),"mmm-yy") | E19: =TEXT(EDATE(TODAY(),-9),"mmm-yy") | F19: =TEXT(EDATE(TODAY(),-8),"mmm-yy") | G19: =TEXT(EDATE(TODAY(),-7),"mmm-yy") | H19: =TEXT(EDATE(TODAY(),-6),"mmm-yy") | I19: =TEXT(EDATE(TODAY(),-5),"mmm-yy") | J19: =TEXT(EDATE(TODAY(),-4),"mmm-yy") | K19: =TEXT(EDATE(TODAY(),-3),"mmm-yy") | L19: =TEXT(EDATE(TODAY(),-2),"mmm-yy") | M19: =TEXT(EDATE(TODAY(),-1),"mmm-yy") | N19: =TEXT(EDATE(TODAY(),0),"mmm-yy")
C20: =CUBEVALUE("ThisWorkbookDataModel","[Measures].[Gross Margin %]","[DIM_Date].[Year].&["&YEAR(EDATE(TODAY(),-11))&"]","[DIM_Date].[Month].&["&MONTH(EDATE(TODAY(),-11))&"]") | D20: =CUBEVALUE("ThisWorkbookDataModel","[Measures].[Gross Margin %]","[DIM_Date].[Year].&["&YEAR(EDATE(TODAY(),-10))&"]","[DIM_Date].[Month].&["&MONTH(EDATE(TODAY(),-10))&"]") | E20: =CUBEVALUE("ThisWorkbookDataModel","[Measures].[Gross Margin %]","[DIM_Date].[Year].&["&YEAR(EDATE(TODAY(),-9))&"]","[DIM_Date].[Month].&["&MONTH(EDATE(TODAY(),-9))&"]") | F20: =CUBEVALUE("ThisWorkbookDataModel","[Measures].[Gross Margin %]","[DIM_Date].[Year].&["&YEAR(EDATE(TODAY(),-8))&"]","[DIM_Date].[Month].&["&MONTH(EDATE(TODAY(),-8))&"]") | G20: =CUBEVALUE("ThisWorkbookDataModel","[Measures].[Gross Margin %]","[DIM_Date].[Year].&["&YEAR(EDATE(TODAY(),-7))&"]","[DIM_Date].[Month].&["&MONTH(EDATE(TODAY(),-7))&"]") | H20: =CUBEVALUE("ThisWorkbookDataModel","[Measures].[Gross Margin %]","[DIM_Date].[Year].&["&YEAR(EDATE(TODAY(),-6))&"]","[DIM_Date].[Month].&["&MONTH(EDATE(TODAY(),-6))&"]") | I20: =CUBEVALUE("ThisWorkbookDataModel","[Measures].[Gross Margin %]","[DIM_Date].[Year].&["&YEAR(EDATE(TODAY(),-5))&"]","[DIM_Date].[Month].&["&MONTH(EDATE(TODAY(),-5))&"]") | J20: =CUBEVALUE("ThisWorkbookDataModel","[Measures].[Gross Margin %]","[DIM_Date].[Year].&["&YEAR(EDATE(TODAY(),-4))&"]","[DIM_Date].[Month].&["&MONTH(EDATE(TODAY(),-4))&"]") | K20: =CUBEVALUE("ThisWorkbookDataModel","[Measures].[Gross Margin %]","[DIM_Date].[Year].&["&YEAR(EDATE(TODAY(),-3))&"]","[DIM_Date].[Month].&["&MONTH(EDATE(TODAY(),-3))&"]") | L20: =CUBEVALUE("ThisWorkbookDataModel","[Measures].[Gross Margin %]","[DIM_Date].[Year].&["&YEAR(EDATE(TODAY(),-2))&"]","[DIM_Date].[Month].&["&MONTH(EDATE(TODAY(),-2))&"]") | M20: =CUBEVALUE("ThisWorkbookDataModel","[Measures].[Gross Margin %]","[DIM_Date].[Year].&["&YEAR(EDATE(TODAY(),-1))&"]","[DIM_Date].[Month].&["&MONTH(EDATE(TODAY(),-1))&"]") | N20: =CUBEVALUE("ThisWorkbookDataModel","[Measures].[Gross Margin %]","[DIM_Date].[Year].&["&YEAR(EDATE(TODAY(),0))&"]","[DIM_Date].[Month].&["&MONTH(EDATE(TODAY(),0))&"]")
B38: MARGIN BY PRODUCT
B39: Margin by Product (Top 8 by Gross Profit) | G39: =CUBESET("ThisWorkbookDataModel","{[DIM_Product].[Title].Children}","Margin by Product (Top 8 by Gross Profit)","BDESC","[Measures].[Gross Profit]")
B40: Title | C40: Gross Profit | D40: Gross Margin %
